[section#except.uncaught
    [:en] The [`std::uncaught_exceptions()] function
    [:zh_CN] [`std::uncaught_exceptions()] 函数
]
[%@library uncaught_exceptions]

[para]
[:en]
An exception is considered uncaught after completing the initialization of the
exception object ([#except.throw]) until completing the activation of a handler
for the exception ([#except.handle]).
[:zh_CN]
在一个异常对象的初始化完成之后（[#except.throw]）直到该异常的某个处理器完成激活
（[#except.handle]）之前，异常被当作未被捕获。

[:en]
This includes stack unwinding.
[:zh_CN]
其中包括了堆栈解退。

[:en]
If the exception is rethrown ([#expr.throw]), it is considered uncaught from the
point of rethrow until the rethrown exception is caught again.
[:zh_CN]
若该异常被重新抛出（[#expr.throw]），则从重新抛出点直到重新抛出的异常被再次捕获
之前，异常被当作未被捕获。

[:en]
The function [`std::uncaught_exceptions()] ([#uncaught.exceptions]) returns the
number of uncaught exceptions.
[:zh_CN]
函数 [`std::uncaught_exceptions()]（[#uncaught.exceptions]）返回未捕获异常的数量
。
